2023-07-13 23:00:08,297 ERROR: Exception on / [GET] [in /home/egoza/PycharmProjects/LUDAPROJECT/venv/lib/python3.10/site-packages/flask/app.py:1414]
Traceback (most recent call last):
  File "/home/egoza/PycharmProjects/LUDAPROJECT/venv/lib/python3.10/site-packages/sqlalchemy/engine/base.py", line 1965, in _exec_single_context
    self.dialect.do_execute(
  File "/home/egoza/PycharmProjects/LUDAPROJECT/venv/lib/python3.10/site-packages/sqlalchemy/engine/default.py", line 921, in do_execute
    cursor.execute(statement, parameters)
sqlite3.OperationalError: no such table: user

The above exception was the direct cause of the following exception:

Traceback (most recent call last):
  File "/home/egoza/PycharmProjects/LUDAPROJECT/venv/lib/python3.10/site-packages/flask/app.py", line 2190, in wsgi_app
    response = self.full_dispatch_request()
  File "/home/egoza/PycharmProjects/LUDAPROJECT/venv/lib/python3.10/site-packages/flask/app.py", line 1486, in full_dispatch_request
    rv = self.handle_user_exception(e)
  File "/home/egoza/PycharmProjects/LUDAPROJECT/venv/lib/python3.10/site-packages/flask/app.py", line 1482, in full_dispatch_request
    rv = self.preprocess_request()
  File "/home/egoza/PycharmProjects/LUDAPROJECT/venv/lib/python3.10/site-packages/flask/app.py", line 1974, in preprocess_request
    rv = self.ensure_sync(before_func)()
  File "/home/egoza/PycharmProjects/LUDAPROJECT/app/routes.py", line 14, in before_request
    if current_user.is_authenticated:
  File "/home/egoza/PycharmProjects/LUDAPROJECT/venv/lib/python3.10/site-packages/werkzeug/local.py", line 311, in __get__
    obj = instance._get_current_object()
  File "/home/egoza/PycharmProjects/LUDAPROJECT/venv/lib/python3.10/site-packages/werkzeug/local.py", line 515, in _get_current_object
    return get_name(local())  # type: ignore
  File "/home/egoza/PycharmProjects/LUDAPROJECT/venv/lib/python3.10/site-packages/flask_login/utils.py", line 25, in <lambda>
    current_user = LocalProxy(lambda: _get_user())
  File "/home/egoza/PycharmProjects/LUDAPROJECT/venv/lib/python3.10/site-packages/flask_login/utils.py", line 372, in _get_user
    current_app.login_manager._load_user()
  File "/home/egoza/PycharmProjects/LUDAPROJECT/venv/lib/python3.10/site-packages/flask_login/login_manager.py", line 364, in _load_user
    user = self._user_callback(user_id)
  File "/home/egoza/PycharmProjects/LUDAPROJECT/app/models.py", line 61, in load_user
    return User.query.get(int(id))
  File "<string>", line 2, in get
  File "/home/egoza/PycharmProjects/LUDAPROJECT/venv/lib/python3.10/site-packages/sqlalchemy/util/deprecations.py", line 386, in warned
    return fn(*args, **kwargs)  # type: ignore[no-any-return]
  File "/home/egoza/PycharmProjects/LUDAPROJECT/venv/lib/python3.10/site-packages/sqlalchemy/orm/query.py", line 1130, in get
    return self._get_impl(ident, loading.load_on_pk_identity)
  File "/home/egoza/PycharmProjects/LUDAPROJECT/venv/lib/python3.10/site-packages/sqlalchemy/orm/query.py", line 1139, in _get_impl
    return self.session._get_impl(
  File "/home/egoza/PycharmProjects/LUDAPROJECT/venv/lib/python3.10/site-packages/sqlalchemy/orm/session.py", line 3684, in _get_impl
    return db_load_fn(
  File "/home/egoza/PycharmProjects/LUDAPROJECT/venv/lib/python3.10/site-packages/sqlalchemy/orm/loading.py", line 666, in load_on_pk_identity
    session.execute(
  File "/home/egoza/PycharmProjects/LUDAPROJECT/venv/lib/python3.10/site-packages/sqlalchemy/orm/session.py", line 2246, in execute
    return self._execute_internal(
  File "/home/egoza/PycharmProjects/LUDAPROJECT/venv/lib/python3.10/site-packages/sqlalchemy/orm/session.py", line 2141, in _execute_internal
    result: Result[Any] = compile_state_cls.orm_execute_statement(
  File "/home/egoza/PycharmProjects/LUDAPROJECT/venv/lib/python3.10/site-packages/sqlalchemy/orm/context.py", line 293, in orm_execute_statement
    result = conn.execute(
  File "/home/egoza/PycharmProjects/LUDAPROJECT/venv/lib/python3.10/site-packages/sqlalchemy/engine/base.py", line 1412, in execute
    return meth(
  File "/home/egoza/PycharmProjects/LUDAPROJECT/venv/lib/python3.10/site-packages/sqlalchemy/sql/elements.py", line 483, in _execute_on_connection
    return connection._execute_clauseelement(
  File "/home/egoza/PycharmProjects/LUDAPROJECT/venv/lib/python3.10/site-packages/sqlalchemy/engine/base.py", line 1635, in _execute_clauseelement
    ret = self._execute_context(
  File "/home/egoza/PycharmProjects/LUDAPROJECT/venv/lib/python3.10/site-packages/sqlalchemy/engine/base.py", line 1844, in _execute_context
    return self._exec_single_context(
  File "/home/egoza/PycharmProjects/LUDAPROJECT/venv/lib/python3.10/site-packages/sqlalchemy/engine/base.py", line 1984, in _exec_single_context
    self._handle_dbapi_exception(
  File "/home/egoza/PycharmProjects/LUDAPROJECT/venv/lib/python3.10/site-packages/sqlalchemy/engine/base.py", line 2339, in _handle_dbapi_exception
    raise sqlalchemy_exception.with_traceback(exc_info[2]) from e
  File "/home/egoza/PycharmProjects/LUDAPROJECT/venv/lib/python3.10/site-packages/sqlalchemy/engine/base.py", line 1965, in _exec_single_context
    self.dialect.do_execute(
  File "/home/egoza/PycharmProjects/LUDAPROJECT/venv/lib/python3.10/site-packages/sqlalchemy/engine/default.py", line 921, in do_execute
    cursor.execute(statement, parameters)
sqlalchemy.exc.OperationalError: (sqlite3.OperationalError) no such table: user
[SQL: SELECT user.id AS user_id, user.username AS user_username, user.email AS user_email, user.avatar AS user_avatar, user.password_hash AS user_password_hash, user.about_me AS user_about_me, user.last_seen AS user_last_seen 
FROM user 
WHERE user.id = ?]
[parameters: (6,)]
(Background on this error at: https://sqlalche.me/e/20/e3q8)
2023-07-13 23:01:16,042 INFO: Ludaproject startup [in /home/egoza/PycharmProjects/LUDAPROJECT/app/__init__.py:44]
2023-07-13 23:01:24,499 INFO: Ludaproject startup [in /home/egoza/PycharmProjects/LUDAPROJECT/app/__init__.py:44]
2023-07-13 23:01:30,256 INFO: Ludaproject startup [in /home/egoza/PycharmProjects/LUDAPROJECT/app/__init__.py:44]
2023-07-13 23:03:26,532 INFO: Ludaproject startup [in /home/egoza/PycharmProjects/LUDAPROJECT/app/__init__.py:44]
2023-07-13 23:06:36,156 INFO: Ludaproject startup [in /home/egoza/PycharmProjects/LUDAPROJECT/app/__init__.py:44]
2023-07-13 23:11:08,979 INFO: Ludaproject startup [in /home/egoza/PycharmProjects/LUDAPROJECT/app/__init__.py:44]
2023-07-13 23:17:17,898 INFO: Ludaproject startup [in /home/egoza/PycharmProjects/LUDAPROJECT/app/__init__.py:44]
2023-07-13 23:19:08,610 INFO: Ludaproject startup [in /home/egoza/PycharmProjects/LUDAPROJECT/app/__init__.py:44]
2023-07-13 23:19:11,362 ERROR: Exception on /user/Varg [GET] [in /home/egoza/PycharmProjects/LUDAPROJECT/venv/lib/python3.10/site-packages/flask/app.py:1414]
Traceback (most recent call last):
  File "/home/egoza/PycharmProjects/LUDAPROJECT/venv/lib/python3.10/site-packages/flask/app.py", line 2190, in wsgi_app
    response = self.full_dispatch_request()
  File "/home/egoza/PycharmProjects/LUDAPROJECT/venv/lib/python3.10/site-packages/flask/app.py", line 1486, in full_dispatch_request
    rv = self.handle_user_exception(e)
  File "/home/egoza/PycharmProjects/LUDAPROJECT/venv/lib/python3.10/site-packages/flask/app.py", line 1484, in full_dispatch_request
    rv = self.dispatch_request()
  File "/home/egoza/PycharmProjects/LUDAPROJECT/venv/lib/python3.10/site-packages/flask/app.py", line 1469, in dispatch_request
    return self.ensure_sync(self.view_functions[rule.endpoint])(**view_args)
  File "/home/egoza/PycharmProjects/LUDAPROJECT/venv/lib/python3.10/site-packages/flask_login/utils.py", line 290, in decorated_view
    return current_app.ensure_sync(func)(*args, **kwargs)
  File "/home/egoza/PycharmProjects/LUDAPROJECT/app/routes.py", line 39, in user
    return render_template('user.html', user=user, form=form)
  File "/home/egoza/PycharmProjects/LUDAPROJECT/venv/lib/python3.10/site-packages/flask/templating.py", line 151, in render_template
    return _render(app, template, context)
  File "/home/egoza/PycharmProjects/LUDAPROJECT/venv/lib/python3.10/site-packages/flask/templating.py", line 132, in _render
    rv = template.render(context)
  File "/home/egoza/PycharmProjects/LUDAPROJECT/venv/lib/python3.10/site-packages/jinja2/environment.py", line 1301, in render
    self.environment.handle_exception()
  File "/home/egoza/PycharmProjects/LUDAPROJECT/venv/lib/python3.10/site-packages/jinja2/environment.py", line 936, in handle_exception
    raise rewrite_traceback_stack(source=source)
  File "/home/egoza/PycharmProjects/LUDAPROJECT/app/templates/user.html", line 1, in top-level template code
    {% extends "base.html" %}
  File "/home/egoza/PycharmProjects/LUDAPROJECT/app/templates/base.html", line 32, in top-level template code
    {% block content %}{% endblock %}
  File "/home/egoza/PycharmProjects/LUDAPROJECT/app/templates/user.html", line 9, in block 'content'
    <td><img src="{{ url_for('static', filename='profile_pics/' + avatar_files[1]) }}" alt="Avatar of user {{ user.username }}" width="128"></td>
  File "/home/egoza/PycharmProjects/LUDAPROJECT/venv/lib/python3.10/site-packages/jinja2/environment.py", line 466, in getitem
    return obj[argument]
jinja2.exceptions.UndefinedError: 'avatar_files' is undefined
2023-07-13 23:19:52,899 INFO: Ludaproject startup [in /home/egoza/PycharmProjects/LUDAPROJECT/app/__init__.py:44]
2023-07-13 23:20:33,590 INFO: Ludaproject startup [in /home/egoza/PycharmProjects/LUDAPROJECT/app/__init__.py:44]
2023-07-13 23:22:59,661 INFO: Ludaproject startup [in /home/egoza/PycharmProjects/LUDAPROJECT/app/__init__.py:44]
2023-07-13 23:25:06,067 INFO: Ludaproject startup [in /home/egoza/PycharmProjects/LUDAPROJECT/app/__init__.py:44]
2023-07-13 23:26:29,125 INFO: Ludaproject startup [in /home/egoza/PycharmProjects/LUDAPROJECT/app/__init__.py:44]
