2024-02-09 04:06:50,615 INFO: Luda startup [in /home/egoza/PycharmProjects/LUDAPROJECT/app/__init__.py:71]
2024-02-09 04:06:53,048 ERROR: Exception on / [GET] [in /home/egoza/PycharmProjects/LUDAPROJECT/venv/lib/python3.10/site-packages/flask/app.py:1414]
Traceback (most recent call last):
  File "/home/egoza/PycharmProjects/LUDAPROJECT/venv/lib/python3.10/site-packages/flask/app.py", line 2190, in wsgi_app
    response = self.full_dispatch_request()
  File "/home/egoza/PycharmProjects/LUDAPROJECT/venv/lib/python3.10/site-packages/flask/app.py", line 1486, in full_dispatch_request
    rv = self.handle_user_exception(e)
  File "/home/egoza/PycharmProjects/LUDAPROJECT/venv/lib/python3.10/site-packages/flask/app.py", line 1482, in full_dispatch_request
    rv = self.preprocess_request()
  File "/home/egoza/PycharmProjects/LUDAPROJECT/venv/lib/python3.10/site-packages/flask/app.py", line 1974, in preprocess_request
    rv = self.ensure_sync(before_func)()
  File "/home/egoza/PycharmProjects/LUDAPROJECT/app/main/routes.py", line 18, in before_request
    db.session.commit()
  File "/home/egoza/PycharmProjects/LUDAPROJECT/venv/lib/python3.10/site-packages/sqlalchemy/orm/scoping.py", line 552, in commit
    return self._proxied.commit()
  File "/home/egoza/PycharmProjects/LUDAPROJECT/venv/lib/python3.10/site-packages/sqlalchemy/orm/session.py", line 1920, in commit
    trans.commit(_to_root=True)
  File "<string>", line 2, in commit
  File "/home/egoza/PycharmProjects/LUDAPROJECT/venv/lib/python3.10/site-packages/sqlalchemy/orm/state_changes.py", line 139, in _go
    ret_value = fn(self, *arg, **kw)
  File "/home/egoza/PycharmProjects/LUDAPROJECT/venv/lib/python3.10/site-packages/sqlalchemy/orm/session.py", line 1246, in commit
    self.session.dispatch.after_commit(self.session)
  File "/home/egoza/PycharmProjects/LUDAPROJECT/venv/lib/python3.10/site-packages/sqlalchemy/event/attr.py", line 378, in __call__
    fn(*args, **kw)
  File "/home/egoza/PycharmProjects/LUDAPROJECT/app/models.py", line 38, in after_commit
    add_to_index(obj.__tablename__, obj)
  File "/home/egoza/PycharmProjects/LUDAPROJECT/app/search.py", line 10, in add_to_index
    current_app.elasticsearch.index(index=index, id=model.id, body=payload)
  File "/home/egoza/PycharmProjects/LUDAPROJECT/venv/lib/python3.10/site-packages/elasticsearch/_sync/client/utils.py", line 414, in wrapped
    return api(*args, **kwargs)
  File "/home/egoza/PycharmProjects/LUDAPROJECT/venv/lib/python3.10/site-packages/elasticsearch/_sync/client/__init__.py", line 2318, in index
    return self.perform_request(  # type: ignore[return-value]
  File "/home/egoza/PycharmProjects/LUDAPROJECT/venv/lib/python3.10/site-packages/elasticsearch/_sync/client/_base.py", line 285, in perform_request
    meta, resp_body = self.transport.perform_request(
  File "/home/egoza/PycharmProjects/LUDAPROJECT/venv/lib/python3.10/site-packages/elastic_transport/_transport.py", line 329, in perform_request
    meta, raw_data = node.perform_request(
  File "/home/egoza/PycharmProjects/LUDAPROJECT/venv/lib/python3.10/site-packages/elastic_transport/_node/_http_urllib3.py", line 199, in perform_request
    raise err from None
elastic_transport.ConnectionError: Connection error caused by: ConnectionError(Connection error caused by: NewConnectionError(<urllib3.connection.HTTPConnection object at 0x7f22cf511720>: Failed to establish a new connection: [Errno 111] Connection refused))
2024-02-09 04:10:22,273 INFO: Luda startup [in /home/egoza/PycharmProjects/LUDAPROJECT/app/__init__.py:71]
2024-02-09 04:10:23,877 ERROR: Exception on / [GET] [in /home/egoza/PycharmProjects/LUDAPROJECT/venv/lib/python3.10/site-packages/flask/app.py:1414]
Traceback (most recent call last):
  File "/home/egoza/PycharmProjects/LUDAPROJECT/venv/lib/python3.10/site-packages/flask/app.py", line 2190, in wsgi_app
    response = self.full_dispatch_request()
  File "/home/egoza/PycharmProjects/LUDAPROJECT/venv/lib/python3.10/site-packages/flask/app.py", line 1486, in full_dispatch_request
    rv = self.handle_user_exception(e)
  File "/home/egoza/PycharmProjects/LUDAPROJECT/venv/lib/python3.10/site-packages/flask/app.py", line 1482, in full_dispatch_request
    rv = self.preprocess_request()
  File "/home/egoza/PycharmProjects/LUDAPROJECT/venv/lib/python3.10/site-packages/flask/app.py", line 1974, in preprocess_request
    rv = self.ensure_sync(before_func)()
  File "/home/egoza/PycharmProjects/LUDAPROJECT/app/main/routes.py", line 18, in before_request
    db.session.commit()
  File "/home/egoza/PycharmProjects/LUDAPROJECT/venv/lib/python3.10/site-packages/sqlalchemy/orm/scoping.py", line 552, in commit
    return self._proxied.commit()
  File "/home/egoza/PycharmProjects/LUDAPROJECT/venv/lib/python3.10/site-packages/sqlalchemy/orm/session.py", line 1920, in commit
    trans.commit(_to_root=True)
  File "<string>", line 2, in commit
  File "/home/egoza/PycharmProjects/LUDAPROJECT/venv/lib/python3.10/site-packages/sqlalchemy/orm/state_changes.py", line 139, in _go
    ret_value = fn(self, *arg, **kw)
  File "/home/egoza/PycharmProjects/LUDAPROJECT/venv/lib/python3.10/site-packages/sqlalchemy/orm/session.py", line 1246, in commit
    self.session.dispatch.after_commit(self.session)
  File "/home/egoza/PycharmProjects/LUDAPROJECT/venv/lib/python3.10/site-packages/sqlalchemy/event/attr.py", line 378, in __call__
    fn(*args, **kw)
  File "/home/egoza/PycharmProjects/LUDAPROJECT/app/models.py", line 38, in after_commit
    add_to_index(obj.__tablename__, obj)
  File "/home/egoza/PycharmProjects/LUDAPROJECT/app/search.py", line 5, in add_to_index
    if not current_app.elasticsearch:
AttributeError: 'Flask' object has no attribute 'elasticsearch'
2024-02-09 04:10:57,554 INFO: Luda startup [in /home/egoza/PycharmProjects/LUDAPROJECT/app/__init__.py:71]
