2024-02-09 04:11:00,392 ERROR: Exception on / [GET] [in /home/egoza/PycharmProjects/LUDAPROJECT/venv/lib/python3.10/site-packages/flask/app.py:1414]
Traceback (most recent call last):
  File "/home/egoza/PycharmProjects/LUDAPROJECT/venv/lib/python3.10/site-packages/sqlalchemy/engine/base.py", line 1965, in _exec_single_context
    self.dialect.do_execute(
  File "/home/egoza/PycharmProjects/LUDAPROJECT/venv/lib/python3.10/site-packages/sqlalchemy/engine/default.py", line 921, in do_execute
    cursor.execute(statement, parameters)
sqlite3.OperationalError: no such table: user

The above exception was the direct cause of the following exception:

Traceback (most recent call last):
  File "/home/egoza/PycharmProjects/LUDAPROJECT/venv/lib/python3.10/site-packages/flask/app.py", line 2190, in wsgi_app
    response = self.full_dispatch_request()
  File "/home/egoza/PycharmProjects/LUDAPROJECT/venv/lib/python3.10/site-packages/flask/app.py", line 1486, in full_dispatch_request
    rv = self.handle_user_exception(e)
  File "/home/egoza/PycharmProjects/LUDAPROJECT/venv/lib/python3.10/site-packages/flask/app.py", line 1482, in full_dispatch_request
    rv = self.preprocess_request()
  File "/home/egoza/PycharmProjects/LUDAPROJECT/venv/lib/python3.10/site-packages/flask/app.py", line 1974, in preprocess_request
    rv = self.ensure_sync(before_func)()
  File "/home/egoza/PycharmProjects/LUDAPROJECT/app/main/routes.py", line 16, in before_request
    if current_user.is_authenticated:
  File "/home/egoza/PycharmProjects/LUDAPROJECT/venv/lib/python3.10/site-packages/werkzeug/local.py", line 311, in __get__
    obj = instance._get_current_object()
  File "/home/egoza/PycharmProjects/LUDAPROJECT/venv/lib/python3.10/site-packages/werkzeug/local.py", line 515, in _get_current_object
    return get_name(local())  # type: ignore
  File "/home/egoza/PycharmProjects/LUDAPROJECT/venv/lib/python3.10/site-packages/flask_login/utils.py", line 25, in <lambda>
    current_user = LocalProxy(lambda: _get_user())
  File "/home/egoza/PycharmProjects/LUDAPROJECT/venv/lib/python3.10/site-packages/flask_login/utils.py", line 372, in _get_user
    current_app.login_manager._load_user()
  File "/home/egoza/PycharmProjects/LUDAPROJECT/venv/lib/python3.10/site-packages/flask_login/login_manager.py", line 364, in _load_user
    user = self._user_callback(user_id)
  File "/home/egoza/PycharmProjects/LUDAPROJECT/app/models.py", line 129, in load_user
    return User.query.get(int(id))
  File "<string>", line 2, in get
  File "/home/egoza/PycharmProjects/LUDAPROJECT/venv/lib/python3.10/site-packages/sqlalchemy/util/deprecations.py", line 386, in warned
    return fn(*args, **kwargs)  # type: ignore[no-any-return]
  File "/home/egoza/PycharmProjects/LUDAPROJECT/venv/lib/python3.10/site-packages/sqlalchemy/orm/query.py", line 1130, in get
    return self._get_impl(ident, loading.load_on_pk_identity)
  File "/home/egoza/PycharmProjects/LUDAPROJECT/venv/lib/python3.10/site-packages/sqlalchemy/orm/query.py", line 1139, in _get_impl
    return self.session._get_impl(
  File "/home/egoza/PycharmProjects/LUDAPROJECT/venv/lib/python3.10/site-packages/sqlalchemy/orm/session.py", line 3684, in _get_impl
    return db_load_fn(
  File "/home/egoza/PycharmProjects/LUDAPROJECT/venv/lib/python3.10/site-packages/sqlalchemy/orm/loading.py", line 666, in load_on_pk_identity
    session.execute(
  File "/home/egoza/PycharmProjects/LUDAPROJECT/venv/lib/python3.10/site-packages/sqlalchemy/orm/session.py", line 2246, in execute
    return self._execute_internal(
  File "/home/egoza/PycharmProjects/LUDAPROJECT/venv/lib/python3.10/site-packages/sqlalchemy/orm/session.py", line 2141, in _execute_internal
    result: Result[Any] = compile_state_cls.orm_execute_statement(
  File "/home/egoza/PycharmProjects/LUDAPROJECT/venv/lib/python3.10/site-packages/sqlalchemy/orm/context.py", line 293, in orm_execute_statement
    result = conn.execute(
  File "/home/egoza/PycharmProjects/LUDAPROJECT/venv/lib/python3.10/site-packages/sqlalchemy/engine/base.py", line 1412, in execute
    return meth(
  File "/home/egoza/PycharmProjects/LUDAPROJECT/venv/lib/python3.10/site-packages/sqlalchemy/sql/elements.py", line 483, in _execute_on_connection
    return connection._execute_clauseelement(
  File "/home/egoza/PycharmProjects/LUDAPROJECT/venv/lib/python3.10/site-packages/sqlalchemy/engine/base.py", line 1635, in _execute_clauseelement
    ret = self._execute_context(
  File "/home/egoza/PycharmProjects/LUDAPROJECT/venv/lib/python3.10/site-packages/sqlalchemy/engine/base.py", line 1844, in _execute_context
    return self._exec_single_context(
  File "/home/egoza/PycharmProjects/LUDAPROJECT/venv/lib/python3.10/site-packages/sqlalchemy/engine/base.py", line 1984, in _exec_single_context
    self._handle_dbapi_exception(
  File "/home/egoza/PycharmProjects/LUDAPROJECT/venv/lib/python3.10/site-packages/sqlalchemy/engine/base.py", line 2339, in _handle_dbapi_exception
    raise sqlalchemy_exception.with_traceback(exc_info[2]) from e
  File "/home/egoza/PycharmProjects/LUDAPROJECT/venv/lib/python3.10/site-packages/sqlalchemy/engine/base.py", line 1965, in _exec_single_context
    self.dialect.do_execute(
  File "/home/egoza/PycharmProjects/LUDAPROJECT/venv/lib/python3.10/site-packages/sqlalchemy/engine/default.py", line 921, in do_execute
    cursor.execute(statement, parameters)
sqlalchemy.exc.OperationalError: (sqlite3.OperationalError) no such table: user
[SQL: SELECT user.id AS user_id, user.username AS user_username, user.email AS user_email, user.password_hash AS user_password_hash, user.about_me AS user_about_me, user.last_seen AS user_last_seen 
FROM user 
WHERE user.id = ?]
[parameters: (6,)]
(Background on this error at: https://sqlalche.me/e/20/e3q8)
2024-02-09 04:12:05,487 INFO: Luda startup [in /home/egoza/PycharmProjects/LUDAPROJECT/app/__init__.py:71]
2024-02-09 04:12:37,465 INFO: Luda startup [in /home/egoza/PycharmProjects/LUDAPROJECT/app/__init__.py:71]
2024-02-09 04:12:59,295 INFO: Luda startup [in /home/egoza/PycharmProjects/LUDAPROJECT/app/__init__.py:71]
2024-02-09 04:13:06,551 INFO: Luda startup [in /home/egoza/PycharmProjects/LUDAPROJECT/app/__init__.py:71]
2024-02-09 04:13:12,420 INFO: Luda startup [in /home/egoza/PycharmProjects/LUDAPROJECT/app/__init__.py:71]
